Workbook

Sheet Dashboard
A1: Quacked — Executive Dashboard
A2: Cohort- and seasonality-based financial model — illustrative planning scenarios for funding applications and strategic planning, not GAAP forecasts.
A4: Key Metrics — Base Case
A5: Year 3 Exit ARR | D5: Peak Monthly Subscribers | G5: Blended 3-Yr Gross Margin | J5: 3-Year Cumulative Revenue
A6: ='Scenario Summary'!$G$7 -> 290550.73 | D6: =MAX('Forecast - Base'!$M$5:$M$40) -> 834.91589 | G6: =SUM('Forecast - Base'!$S$5:$S$40)/SUM('Forecast - Base'!$O$5:$O$40) -> 0.99448276 | J6: =SUM('Forecast - Base'!$O$5:$O$40) -> 272887.11
A8: All three scenarios (Conservative / Base / Expansion) are detailed on the Scenario Summary tab and their own Forecast tabs.
A10: Monthly Active Subscribers — Base Case
A29: Exit ARR by Scenario
A48: See Product Expansion tab for the illustrative revenue-by-module breakdown (Expansion scenario, future) and Seasonality tab for the recruiting-calendar chart behind the monthly shape above.

Sheet Read Me
A1: Quacked Financial Model
A2: Cohort- and seasonality-based revenue model — prepared for funding applications and strategic planning (not GAAP reporting)
A4: What changed from the prior model
A5: The previous model assumed flat monthly recurring revenue across 12 months, like a generic SaaS product. This version is rebuilt around the actual consulting recruiting calendar: users subscribe for roughly 2–4 months around a recruiting wave (not a full year), new cohorts arrive every year, and growth is driven by explicit, traceable levers — university expansion, referrals, brand recognition, and (in later phases) product expansion — rather than an assumed growth rate.
A7: How to navigate this workbook
A8: Dashboard | B8: Executive summary — KPIs and headline charts (Base case).
A9: Assumptions | B9: All editable model inputs, by scenario (Conservative / Base / Expansion).
A10: Seasonality | B10: Monthly recruiting-cycle index driving acquisition timing.
A11: Market Expansion | B11: TAM/SAM/SOM by phase (UGA → Southeast → National → Adjacent categories).
A12: Product Expansion | B12: Future modules & ARPU uplift — Expansion scenario only, clearly labeled.
A13: Forecast tabs (x3) | B13: 36-month cohort build per scenario: leads → free → paid → active → churn → referral.
A14: Scenario Summary | B14: Annual roll-up and comparison across all three scenarios.
A15: Sensitivity | B15: Year-3 ARR sensitivity to conversion rate and churn (Base case).
A17: Color legend
A18: Legend:
B19: Blue text | D19: — Editable input
B20: Black text | D20: — Calculated formula
B21: Green text | D21: — Link to another sheet
A23: Every subscriber and revenue figure in this model is traceable to an explicit assumption: seasonality, addressable-market phase, awareness/conversion rate, churn, referral coefficient, repeat-user rate, or (Expansion only) product-expansion ARPU uplift. Nothing is hardcoded growth.

Sheet Assumptions
A1: Model Assumptions
A2: All editable drivers. Blue = input. Values differ by scenario where noted.
A4: Model Horizon
A5: Model start month (Month 1) | C5: 46266 | G5: Aligned to fall internship-recruiting cycle kickoff.
A6: Forecast horizon (months) | C6: 36
A8: Pricing
A9: Driver | C9: Conservative | D9: Base | E9: Expansion | G9: Notes
A10: Starting monthly price ($) | C10: 29 | D10: 29 | E10: 29 | G10: Current Big Duck tier price across all scenarios.
A11: Product-expansion launch month (# ) | C11: 99 | D11: 99 | E11: 19 | G11: 99 = not reached in this scenario within the 36-mo horizon. Expansion: start of Year 2 H2.
A12: Post-expansion monthly price ($) | C12: 29 | D12: 29 | E12: 39 | G12: Expansion only — reflects added modules (qualitative practice, frameworks, exhibits, AI coaching). See Product Expansion tab.
A14: Acquisition Funnel (Lead → Free → Paid)
A15: Driver | C15: Conservative | D15: Base | E15: Expansion | G15: Notes
A16: Starting monthly awareness rate (% of addressable pool who become a lead) | C16: 0.025 | D16: 0.03 | E16: 0.035 | G16: Drives Leads = Addressable Pool × Awareness Rate × Seasonality.
A17: Annual awareness growth (brand recognition / word of mouth) | C17: 0.15 | D17: 0.2 | E17: 0.3 | G17: Compounds awareness rate over the 36-month horizon.
A18: Lead → Free signup rate | C18: 0.4 | D18: 0.5 | E18: 0.55 | G18: Share of leads who create a free account.
A19: Free → Paid conversion rate | C19: 0.18 | D19: 0.2 | E19: 0.25 | G19: Share of free users who subscribe.
A21: Retention & Growth Loops
A22: Driver | C22: Conservative | D22: Base | E22: Expansion | G22: Notes
A23: Monthly churn rate | C23: 0.38 | D23: 0.33 | E23: 0.3 | G23: Implies avg. subscription length of ~2.6 / ~3.0 / ~3.3 months — consistent with a 2–4 month recruiting-cycle subscription, not a 12-month SaaS contract.
A24: Referral coefficient (new paid subs / active sub / month) | C24: 0.015 | D24: 0.02 | E24: 0.03 | G24: Word-of-mouth loop: existing active subscribers generate additional paid subs each month.
A25: Repeat / returning-user rate (annual) | C25: 0.06 | D25: 0.08 | E25: 0.12 | G25: Share of subs active 12 months prior who re-subscribe for the next recruiting cycle (e.g., internship → full-time).
A27: Usage & Cost (Gross Margin Drivers)
A28: Driver | C28: Conservative | D28: Base | E28: Expansion | G28: Notes
A29: Avg. completed cases / active user / month | C29: 10 | D29: 10 | E29: 14 | G29: Expansion is higher — more modules (frameworks, exhibits, AI coaching) each generate usage.
A30: Cost per completed case ($) | C30: 0.016 | D30: 0.016 | E30: 0.016 | G30: Current beta Anthropic API cost assumption — unchanged from prior model.
A32: All dollar figures are illustrative planning assumptions for internal strategy and funding-application use, not GAAP-basis forecasts.
A33: Legend:
B34: Blue text | D34: — Editable input
B35: Black text | D35: — Calculated formula
B36: Green text | D36: — Link to another sheet

Sheet Seasonality
A1: Seasonal Recruiting Calendar
A2: Monthly index of new-subscriber acquisition intensity, mapped to the consulting recruiting cycle.
A4: Recruiting Cycle
A5: Summer prep (Jun–Aug) builds toward Fall internship recruiting (Sep–Nov, the annual peak) → a Winter lull (Dec–Jan) → Spring recruiting (Feb–Apr, a secondary peak for regional/Tier 2/off-cycle roles) → Graduation (May) → the next incoming cohort begins the cycle again.
A7: Month # | B7: Calendar Month | C7: Recruiting Season | D7: Raw Index | E7: Normalized Multiplier
A8: 1 | B8: January | C8: Winter Recruiting | D8: 0.9 | E8: =D8/AVERAGE($D$8:$D$19) -> 0.85714286
A9: 2 | B9: February | C9: Spring Recruiting | D9: 1.1 | E9: =D9/AVERAGE($D$8:$D$19) -> 1.047619
A10: 3 | B10: March | C10: Spring Recruiting (peak) | D10: 1.2 | E10: =D10/AVERAGE($D$8:$D$19) -> 1.1428571
A11: 4 | B11: April | C11: Spring Recruiting | D11: 0.8 | E11: =D11/AVERAGE($D$8:$D$19) -> 0.76190476
A12: 5 | B12: May | C12: Graduation Lull | D12: 0.5 | E12: =D12/AVERAGE($D$8:$D$19) -> 0.47619048
A13: 6 | B13: June | C13: Summer Prep Begins | D13: 0.7 | E13: =D13/AVERAGE($D$8:$D$19) -> 0.66666667
A14: 7 | B14: July | C14: Summer Prep | D14: 1 | E14: =D14/AVERAGE($D$8:$D$19) -> 0.95238095
A15: 8 | B15: August | C15: Summer Prep (ramp) | D15: 1.4 | E15: =D15/AVERAGE($D$8:$D$19) -> 1.3333333
A16: 9 | B16: September | C16: Fall Recruiting (peak) | D16: 1.8 | E16: =D16/AVERAGE($D$8:$D$19) -> 1.7142857
A17: 10 | B17: October | C17: Fall Recruiting | D17: 1.6 | E17: =D17/AVERAGE($D$8:$D$19) -> 1.5238095
A18: 11 | B18: November | C18: Fall Recruiting (wraps) | D18: 1 | E18: =D18/AVERAGE($D$8:$D$19) -> 0.95238095
A19: 12 | B19: December | C19: Winter Lull | D19: 0.6 | E19: =D19/AVERAGE($D$8:$D$19) -> 0.57142857
A21: Normalized Multiplier = Raw Index ÷ average index (so the annual average multiplier is exactly 1.00×). This is what actually feeds the forecast — it isolates the *timing* effect of seasonality from the *level* set by the awareness-rate assumption.

Sheet Market Expansion
A1: Market Expansion — Geographic & Category Phases
A2: Replaces a single static TAM/SAM/SOM with a phased rollout. Each phase adds to the addressable candidate pool at a scenario-specific start month.
A4: Consulting-Focused Phases (Phases 1–4)
A5: Phase | B5: Market | C5: Description | D5: Pool Added | E5: Cumulative Pool | F5: Start — Conservative | G5: Start — Base | H5: Start — Expansion | I5: Notes
A6: Phase 1 | B6: UGA | C6: University of Georgia consulting candidates | D6: 200 | E6: =SUM($D$6:D6) -> 200 | F6: 1 | G6: 1 | H6: 1 | I6: Terry consulting orgs, recruiting records, career-center estimates.
A7: Phase 2 | B7: SEC + Southeast | C7: SEC and target Southeastern university consulting clubs | D7: 4800 | E7: =SUM($D$6:D7) -> 5000 | F7: 13 | G7: 7 | H7: 4 | I7: Aggregate consulting clubs across target Southeastern universities.
A8: Phase 3 | B8: Top National Schools | C8: Top consulting-recruiting schools nationally | D8: 20000 | E8: =SUM($D$6:D8) -> 25000 | F8: 31 | G8: 16 | H8: 10 | I8: Universities with consistent MBB/Tier 2 recruiting presence.
A9: Phase 4 | B9: National Market | C9: Full U.S. consulting-recruiting candidate pool | D9: 25000 | E9: =SUM($D$6:D9) -> 50000 | F9: 99 | G9: 28 | H9: 16 | I9: Rounds out to ~50,000 total U.S. consulting candidates (matches prior TAM).
A11: Start month = model month # (1 = Sep-2026) at which this phase's pool becomes addressable. 99 = not reached within the 36-month horizon for that scenario.
A13: Adjacent Recruiting Categories (Phase 5 — Expansion scenario only)
A14: Investment banking, private equity, corporate strategy, product management, and general business recruiting. Kept structurally separate from the consulting-focused pool above — this is a distinct future market, not blended into the core consulting TAM, and only appears in the Expansion scenario.
A15: Phase | B15: Market | C15: Description | D15: Pool Added | E15: Cumulative Pool | F15: Start — Conservative | G15: Start — Base | H15: Start — Expansion | I15: Notes
A16: Phase 5 | B16: Adjacent Categories | C16: IB / PE / corporate strategy / PM / general business recruiting | D16: 100000 | E16: n/a — separate track | F16: 99 | G16: 99 | H16: 24 | I16: Illustrative pool size; not validated. Requires product breadth beyond quant case prep before pursuing.
A19: Cumulative Addressable Pool Over Time (illustrative, by scenario)
A20: Month # | B20: Conservative | C20: Base | D20: Expansion
A21: 1 | B21: =$D$6+IF($A21>=$F$7,$D$7,0)+IF($A21>=$F$8,$D$8,0)+IF($A21>=$F$9,$D$9,0)+IF($A21>=$F$16,$D$16,0) -> 200 | C21: =$D$6+IF($A21>=$G$7,$D$7,0)+IF($A21>=$G$8,$D$8,0)+IF($A21>=$G$9,$D$9,0)+IF($A21>=$G$16,$D$16,0) -> 200 | D21: =$D$6+IF($A21>=$H$7,$D$7,0)+IF($A21>=$H$8,$D$8,0)+IF($A21>=$H$9,$D$9,0)+IF($A21>=$H$16,$D$16,0) -> 200
A22: 2 | B22: =$D$6+IF($A22>=$F$7,$D$7,0)+IF($A22>=$F$8,$D$8,0)+IF($A22>=$F$9,$D$9,0)+IF($A22>=$F$16,$D$16,0) -> 200 | C22: =$D$6+IF($A22>=$G$7,$D$7,0)+IF($A22>=$G$8,$D$8,0)+IF($A22>=$G$9,$D$9,0)+IF($A22>=$G$16,$D$16,0) -> 200 | D22: =$D$6+IF($A22>=$H$7,$D$7,0)+IF($A22>=$H$8,$D$8,0)+IF($A22>=$H$9,$D$9,0)+IF($A22>=$H$16,$D$16,0) -> 200
A23: 3 | B23: =$D$6+IF($A23>=$F$7,$D$7,0)+IF($A23>=$F$8,$D$8,0)+IF($A23>=$F$9,$D$9,0)+IF($A23>=$F$16,$D$16,0) -> 200 | C23: =$D$6+IF($A23>=$G$7,$D$7,0)+IF($A23>=$G$8,$D$8,0)+IF($A23>=$G$9,$D$9,0)+IF($A23>=$G$16,$D$16,0) -> 200 | D23: =$D$6+IF($A23>=$H$7,$D$7,0)+IF($A23>=$H$8,$D$8,0)+IF($A23>=$H$9,$D$9,0)+IF($A23>=$H$16,$D$16,0) -> 200
A24: 4 | B24: =$D$6+IF($A24>=$F$7,$D$7,0)+IF($A24>=$F$8,$D$8,0)+IF($A24>=$F$9,$D$9,0)+IF($A24>=$F$16,$D$16,0) -> 200 | C24: =$D$6+IF($A24>=$G$7,$D$7,0)+IF($A24>=$G$8,$D$8,0)+IF($A24>=$G$9,$D$9,0)+IF($A24>=$G$16,$D$16,0) -> 200 | D24: =$D$6+IF($A24>=$H$7,$D$7,0)+IF($A24>=$H$8,$D$8,0)+IF($A24>=$H$9,$D$9,0)+IF($A24>=$H$16,$D$16,0) -> 5000
A25: 5 | B25: =$D$6+IF($A25>=$F$7,$D$7,0)+IF($A25>=$F$8,$D$8,0)+IF($A25>=$F$9,$D$9,0)+IF($A25>=$F$16,$D$16,0) -> 200 | C25: =$D$6+IF($A25>=$G$7,$D$7,0)+IF($A25>=$G$8,$D$8,0)+IF($A25>=$G$9,$D$9,0)+IF($A25>=$G$16,$D$16,0) -> 200 | D25: =$D$6+IF($A25>=$H$7,$D$7,0)+IF($A25>=$H$8,$D$8,0)+IF($A25>=$H$9,$D$9,0)+IF($A25>=$H$16,$D$16,0) -> 5000
A26: 6 | B26: =$D$6+IF($A26>=$F$7,$D$7,0)+IF($A26>=$F$8,$D$8,0)+IF($A26>=$F$9,$D$9,0)+IF($A26>=$F$16,$D$16,0) -> 200 | C26: =$D$6+IF($A26>=$G$7,$D$7,0)+IF($A26>=$G$8,$D$8,0)+IF($A26>=$G$9,$D$9,0)+IF($A26>=$G$16,$D$16,0) -> 200 | D26: =$D$6+IF($A26>=$H$7,$D$7,0)+IF($A26>=$H$8,$D$8,0)+IF($A26>=$H$9,$D$9,0)+IF($A26>=$H$16,$D$16,0) -> 5000
A27: 7 | B27: =$D$6+IF($A27>=$F$7,$D$7,0)+IF($A27>=$F$8,$D$8,0)+IF($A27>=$F$9,$D$9,0)+IF($A27>=$F$16,$D$16,0) -> 200 | C27: =$D$6+IF($A27>=$G$7,$D$7,0)+IF($A27>=$G$8,$D$8,0)+IF($A27>=$G$9,$D$9,0)+IF($A27>=$G$16,$D$16,0) -> 5000 | D27: =$D$6+IF($A27>=$H$7,$D$7,0)+IF($A27>=$H$8,$D$8,0)+IF($A27>=$H$9,$D$9,0)+IF($A27>=$H$16,$D$16,0) -> 5000
A28: 8 | B28: =$D$6+IF($A28>=$F$7,$D$7,0)+IF($A28>=$F$8,$D$8,0)+IF($A28>=$F$9,$D$9,0)+IF($A28>=$F$16,$D$16,0) -> 200 | C28: =$D$6+IF($A28>=$G$7,$D$7,0)+IF($A28>=$G$8,$D$8,0)+IF($A28>=$G$9,$D$9,0)+IF($A28>=$G$16,$D$16,0) -> 5000 | D28: =$D$6+IF($A28>=$H$7,$D$7,0)+IF($A28>=$H$8,$D$8,0)+IF($A28>=$H$9,$D$9,0)+IF($A28>=$H$16,$D$16,0) -> 5000
A29: 9 | B29: =$D$6+IF($A29>=$F$7,$D$7,0)+IF($A29>=$F$8,$D$8,0)+IF($A29>=$F$9,$D$9,0)+IF($A29>=$F$16,$D$16,0) -> 200 | C29: =$D$6+IF($A29>=$G$7,$D$7,0)+IF($A29>=$G$8,$D$8,0)+IF($A29>=$G$9,$D$9,0)+IF($A29>=$G$16,$D$16,0) -> 5000 | D29: =$D$6+IF($A29>=$H$7,$D$7,0)+IF($A29>=$H$8,$D$8,0)+IF($A29>=$H$9,$D$9,0)+IF($A29>=$H$16,$D$16,0) -> 5000
A30: 10 | B30: =$D$6+IF($A30>=$F$7,$D$7,0)+IF($A30>=$F$8,$D$8,0)+IF($A30>=$F$9,$D$9,0)+IF($A30>=$F$16,$D$16,0) -> 200 | C30: =$D$6+IF($A30>=$G$7,$D$7,0)+IF($A30>=$G$8,$D$8,0)+IF($A30>=$G$9,$D$9,0)+IF($A30>=$G$16,$D$16,0) -> 5000 | D30: =$D$6+IF($A30>=$H$7,$D$7,0)+IF($A30>=$H$8,$D$8,0)+IF($A30>=$H$9,$D$9,0)+IF($A30>=$H$16,$D$16,0) -> 25000
A31: 11 | B31: =$D$6+IF($A31>=$F$7,$D$7,0)+IF($A31>=$F$8,$D$8,0)+IF($A31>=$F$9,$D$9,0)+IF($A31>=$F$16,$D$16,0) -> 200 | C31: =$D$6+IF($A31>=$G$7,$D$7,0)+IF($A31>=$G$8,$D$8,0)+IF($A31>=$G$9,$D$9,0)+IF($A31>=$G$16,$D$16,0) -> 5000 | D31: =$D$6+IF($A31>=$H$7,$D$7,0)+IF($A31>=$H$8,$D$8,0)+IF($A31>=$H$9,$D$9,0)+IF($A31>=$H$16,$D$16,0) -> 25000
A32: 12 | B32: =$D$6+IF($A32>=$F$7,$D$7,0)+IF($A32>=$F$8,$D$8,0)+IF($A32>=$F$9,$D$9,0)+IF($A32>=$F$16,$D$16,0) -> 200 | C32: =$D$6+IF($A32>=$G$7,$D$7,0)+IF($A32>=$G$8,$D$8,0)+IF($A32>=$G$9,$D$9,0)+IF($A32>=$G$16,$D$16,0) -> 5000 | D32: =$D$6+IF($A32>=$H$7,$D$7,0)+IF($A32>=$H$8,$D$8,0)+IF($A32>=$H$9,$D$9,0)+IF($A32>=$H$16,$D$16,0) -> 25000
... A56: 36 | B56: =$D$6+IF($A56>=$F$7,$D$7,0)+IF($A56>=$F$8,$D$8,0)+IF($A56>=$F$9,$D$9,0)+IF($A56>=$F$16,$D$16,0) -> 25000 | C56: =$D$6+IF($A56>=$G$7,$D$7,0)+IF($A56>=$G$8,$D$8,0)+IF($A56>=$G$9,$D$9,0)+IF($A56>=$G$16,$D$16,0) -> 50000 | D56: =$D$6+IF($A56>=$H$7,$D$7,0)+IF($A56>=$H$8,$D$8,0)+IF($A56>=$H$9,$D$9,0)+IF($A56>=$H$16,$D$16,0) -> 150000
A58: Pool for a given month = sum of every phase whose scenario-specific start month has been reached, including Phase 5 (Adjacent Categories) for the Expansion scenario only.

Sheet Product Expansion
A1: Product Expansion Roadmap (Future Scenario)
A2: Illustrative only — these modules are not current revenue streams. They only appear in the Expansion scenario, starting at the product-expansion launch month.
A4: Quacked's current product is quantitative case-math practice. As it evolves into a broader consulting-recruiting platform, additional modules are expected to increase customer lifetime value, retention, and pricing power. The Expansion scenario models this as a single ARPU step-up (see Assumptions: Post-Expansion Monthly Price); the allocation below is an illustrative breakdown of that uplift across modules, for planning discussion only.
A6: Planned Modules & Illustrative ARPU Allocation
A7: Module | B7: Description | C7: Illustrative Share of Uplift | D7: Illustrative $ / mo | E7: Rationale
A8: Qualitative Case Practice | B8: Structured business-judgment case practice beyond quant math | C8: 0.25 | D8: =C8*(Assumptions!$E$12-Assumptions!$E$10) -> 2.5 | E8: Broadens the product beyond arithmetic into the full case-interview skillset.
A9: Framework Drills | B9: Kahoot-style timed recall & drag-and-drop practice for classic frameworks | C9: 0.15 | D9: =C9*(Assumptions!$E$12-Assumptions!$E$10) -> 1.5 | E9: High engagement, habit-forming, cheap to deliver at scale.
A10: Exhibit / Chart Analysis | B10: Deterministic chart-reading and data-interpretation practice (live: Exhibits beta) | C10: 0.15 | D10: =C10*(Assumptions!$E$12-Assumptions!$E$10) -> 1.5 | E10: Already in active development — natural first monetized add-on.
A11: AI Interview Coaching | B11: AI-moderated mock interviews with structured feedback | C11: 0.25 | D11: =C11*(Assumptions!$E$12-Assumptions!$E$10) -> 2.5 | E11: Highest perceived value; closest substitute for paid human coaching / club prep.
A12: Behavioral Interview Prep | B12: Fit/behavioral question practice and story-bank building | C12: 0.1 | D12: =C12*(Assumptions!$E$12-Assumptions!$E$10) -> 1 | E12: Expected but lower-differentiation add-on relative to competitors.
A13: Recruiter Insights & Analytics | B13: Aggregated, anonymized benchmarking of performance vs. peer cohort | C13: 0.1 | D13: =C13*(Assumptions!$E$12-Assumptions!$E$10) -> 1 | E13: Longer-term data-network-effect feature; monetizes engagement history.
A15: Total | C15: =SUM(C8:C13) -> 1 | D15: =SUM(D8:D13) -> 10
A17: Timing: launches at the product-expansion launch month set on the Assumptions tab (Expansion scenario: Month 19, start of Year 2 H2). Conservative and Base scenarios hold price flat at $29/mo and do not include this uplift, consistent with treating product expansion strictly as a future scenario rather than a current revenue stream.

Sheet Forecast - Conservative
A1: 36-Month Forecast — Conservative Case
A2: Cohort build: Leads → Free → Paid → Active, with churn, referral, and repeat-user loops. All dollar figures illustrative.
A4: Month # | B4: Calendar Month | C4: Year | D4: Addressable Pool | E4: Seasonality Multiplier | F4: Effective Awareness Rate | G4: Leads | H4: Free Signups | I4: Paid Conversions | J4: Referral Subs | K4: Returning Subs | L4: Total New Paying Subs | M4: Active Subs | N4: Monthly Price | O4: Monthly Revenue | P4: Cases / User | Q4: Cost / Case | R4: Monthly COGS | S4: Gross Profit | T4: Gross Margin %
A5: 1 | B5: =EDATE(Assumptions!$C$5,A5-1) -> 46266 | C5: =ROUNDUP(A5/12,0) -> 1 | D5: =INDEX('Market Expansion'!$B$21:$B$56,A5) -> 200 | E5: =INDEX(Seasonality!$E$8:$E$19,MONTH(B5)) -> 1.7142857 | F5: =Assumptions!$C$16*(1+Assumptions!$C$17)^((A5-1)/12) -> 0.025 | G5: =D5*F5*E5 -> 8.5714286 | H5: =G5*Assumptions!$C$18 -> 3.4285714 | I5: =H5*Assumptions!$C$19 -> 0.61714286 | J5: 0 | K5: 0 | L5: =I5+J5+K5 -> 0.61714286 | M5: =L5 -> 0.61714286 | N5: =IF(A5>=Assumptions!$C$11,Assumptions!$C$12,Assumptions!$C$10) -> 29 | O5: =M5*N5 -> 17.897143 | P5: =Assumptions!$C$29 -> 10 | Q5: =Assumptions!$C$30 -> 0.016 | R5: =M5*P5*Q5 -> 0.098742857 | S5: =O5-R5 -> 17.7984 | T5: =IF(O5=0,0,S5/O5) -> 0.99448276
A6: 2 | B6: =EDATE(Assumptions!$C$5,A6-1) -> 46296 | C6: =ROUNDUP(A6/12,0) -> 1 | D6: =INDEX('Market Expansion'!$B$21:$B$56,A6) -> 200 | E6: =INDEX(Seasonality!$E$8:$E$19,MONTH(B6)) -> 1.5238095 | F6: =Assumptions!$C$16*(1+Assumptions!$C$17)^((A6-1)/12) -> 0.025292873 | G6: =D6*F6*E6 -> 7.7083041 | H6: =G6*Assumptions!$C$18 -> 3.0833217 | I6: =H6*Assumptions!$C$19 -> 0.5549979 | J6: =M5*Assumptions!$C$24 -> 0.0092571429 | K6: 0 | L6: =I6+J6+K6 -> 0.56425504 | M6: =L6+M5*(1-Assumptions!$C$23) -> 0.94688361 | N6: =IF(A6>=Assumptions!$C$11,Assumptions!$C$12,Assumptions!$C$10) -> 29 | O6: =M6*N6 -> 27.459625 | P6: =Assumptions!$C$29 -> 10 | Q6: =Assumptions!$C$30 -> 0.016 | R6: =M6*P6*Q6 -> 0.15150138 | S6: =O6-R6 -> 27.308123 | T6: =IF(O6=0,0,S6/O6) -> 0.99448276
A7: 3 | B7: =EDATE(Assumptions!$C$5,A7-1) -> 46327 | C7: =ROUNDUP(A7/12,0) -> 1 | D7: =INDEX('Market Expansion'!$B$21:$B$56,A7) -> 200 | E7: =INDEX(Seasonality!$E$8:$E$19,MONTH(B7)) -> 0.95238095 | F7: =Assumptions!$C$16*(1+Assumptions!$C$17)^((A7-1)/12) -> 0.025589177 | G7: =D7*F7*E7 -> 4.8741289 | H7: =G7*Assumptions!$C$18 -> 1.9496516 | I7: =H7*Assumptions!$C$19 -> 0.35093728 | J7: =M6*Assumptions!$C$24 -> 0.014203254 | K7: 0 | L7: =I7+J7+K7 -> 0.36514054 | M7: =L7+M6*(1-Assumptions!$C$23) -> 0.95220838 | N7: =IF(A7>=Assumptions!$C$11,Assumptions!$C$12,Assumptions!$C$10) -> 29 | O7: =M7*N7 -> 27.614043 | P7: =Assumptions!$C$29 -> 10 | Q7: =Assumptions!$C$30 -> 0.016 | R7: =M7*P7*Q7 -> 0.15235334 | S7: =O7-R7 -> 27.46169 | T7: =IF(O7=0,0,S7/O7) -> 0.99448276
A8: 4 | B8: =EDATE(Assumptions!$C$5,A8-1) -> 46357 | C8: =ROUNDUP(A8/12,0) -> 1 | D8: =INDEX('Market Expansion'!$B$21:$B$56,A8) -> 200 | E8: =INDEX(Seasonality!$E$8:$E$19,MONTH(B8)) -> 0.57142857 | F8: =Assumptions!$C$16*(1+Assumptions!$C$17)^((A8-1)/12) -> 0.025888952 | G8: =D8*F8*E8 -> 2.9587374 | H8: =G8*Assumptions!$C$18 -> 1.1834949 | I8: =H8*Assumptions!$C$19 -> 0.21302909 | J8: =M7*Assumptions!$C$24 -> 0.014283126 | K8: 0 | L8: =I8+J8+K8 -> 0.22731222 | M8: =L8+M7*(1-Assumptions!$C$23) -> 0.81768141 | N8: =IF(A8>=Assumptions!$C$11,Assumptions!$C$12,Assumptions!$C$10) -> 29 | O8: =M8*N8 -> 23.712761 | P8: =Assumptions!$C$29 -> 10 | Q8: =Assumptions!$C$30 -> 0.016 | R8: =M8*P8*Q8 -> 0.13082903 | S8: =O8-R8 -> 23.581932 | T8: =IF(O8=0,0,S8/O8) -> 0.99448276
A9: 5 | B9: =EDATE(Assumptions!$C$5,A9-1) -> 46388 | C9: =ROUNDUP(A9/12,0) -> 1 | D9: =INDEX('Market Expansion'!$B$21:$B$56,A9) -> 200 | E9: =INDEX(Seasonality!$E$8:$E$19,MONTH(B9)) -> 0.85714286 | F9: =Assumptions!$C$16*(1+Assumptions!$C$17)^((A9-1)/12) -> 0.026192239 | G9: =D9*F9*E9 -> 4.4900981 | H9: =G9*Assumptions!$C$18 -> 1.7960392 | I9: =H9*Assumptions!$C$19 -> 0.32328706 | J9: =M8*Assumptions!$C$24 -> 0.012265221 | K9: 0 | L9: =I9+J9+K9 -> 0.33555228 | M9: =L9+M8*(1-Assumptions!$C$23) -> 0.84251476 | N9: =IF(A9>=Assumptions!$C$11,Assumptions!$C$12,Assumptions!$C$10) -> 29 | O9: =M9*N9 -> 24.432928 | P9: =Assumptions!$C$29 -> 10 | Q9: =Assumptions!$C$30 -> 0.016 | R9: =M9*P9*Q9 -> 0.13480236 | S9: =O9-R9 -> 24.298126 | T9: =IF(O9=0,0,S9/O9) -> 0.99448276
A10: 6 | B10: =EDATE(Assumptions!$C$5,A10-1) -> 46419 | C10: =ROUNDUP(A10/12,0) -> 1 | D10: =INDEX('Market Expansion'!$B$21:$B$56,A10) -> 200 | E10: =INDEX(Seasonality!$E$8:$E$19,MONTH(B10)) -> 1.047619 | F10: =Assumptions!$C$16*(1+Assumptions!$C$17)^((A10-1)/12) -> 0.026499079 | G10: =D10*F10*E10 -> 5.5521879 | H10: =G10*Assumptions!$C$18 -> 2.2208752 | I10: =H10*Assumptions!$C$19 -> 0.39975753 | J10: =M9*Assumptions!$C$24 -> 0.012637721 | K10: 0 | L10: =I10+J10+K10 -> 0.41239525 | M10: =L10+M9*(1-Assumptions!$C$23) -> 0.9347544 | N10: =IF(A10>=Assumptions!$C$11,Assumptions!$C$12,Assumptions!$C$10) -> 29 | O10: =M10*N10 -> 27.107878 | P10: =Assumptions!$C$29 -> 10 | Q10: =Assumptions!$C$30 -> 0.016 | R10: =M10*P10*Q10 -> 0.1495607 | S10: =O10-R10 -> 26.958317 | T10: =IF(O10=0,0,S10/O10) -> 0.99448276
A11: 7 | B11: =EDATE(Assumptions!$C$5,A11-1) -> 46447 | C11: =ROUNDUP(A11/12,0) -> 1 | D11: =INDEX('Market Expansion'!$B$21:$B$56,A11) -> 200 | E11: =INDEX(Seasonality!$E$8:$E$19,MONTH(B11)) -> 1.1428571 | F11: =Assumptions!$C$16*(1+Assumptions!$C$17)^((A11-1)/12) -> 0.026809513 | G11: =D11*F11*E11 -> 6.1278887 | H11: =G11*Assumptions!$C$18 -> 2.4511555 | I11: =H11*Assumptions!$C$19 -> 0.44120799 | J11: =M10*Assumptions!$C$24 -> 0.014021316 | K11: 0 | L11: =I11+J11+K11 -> 0.45522931 | M11: =L11+M10*(1-Assumptions!$C$23) -> 1.034777 | N11: =IF(A11>=Assumptions!$C$11,Assumptions!$C$12,Assumptions!$C$10) -> 29 | O11: =M11*N11 -> 30.008534 | P11: =Assumptions!$C$29 -> 10 | Q11: =Assumptions!$C$30 -> 0.016 | R11: =M11*P11*Q11 -> 0.16556433 | S11: =O11-R11 -> 29.84297 | T11: =IF(O11=0,0,S11/O11) -> 0.99448276
A12: 8 | B12: =EDATE(Assumptions!$C$5,A12-1) -> 46478 | C12: =ROUNDUP(A12/12,0) -> 1 | D12: =INDEX('Market Expansion'!$B$21:$B$56,A12) -> 200 | E12: =INDEX(Seasonality!$E$8:$E$19,MONTH(B12)) -> 0.76190476 | F12: =Assumptions!$C$16*(1+Assumptions!$C$17)^((A12-1)/12) -> 0.027123584 | G12: =D12*F12*E12 -> 4.1331176 | H12: =G12*Assumptions!$C$18 -> 1.6532471 | I12: =H12*Assumptions!$C$19 -> 0.29758447 | J12: =M11*Assumptions!$C$24 -> 0.015521656 | K12: 0 | L12: =I12+J12+K12 -> 0.31310612 | M12: =L12+M11*(1-Assumptions!$C$23) -> 0.95466789 | N12: =IF(A12>=Assumptions!$C$11,Assumptions!$C$12,Assumptions!$C$10) -> 29 | O12: =M12*N12 -> 27.685369 | P12: =Assumptions!$C$29 -> 10 | Q12: =Assumptions!$C$30 -> 0.016 | R12: =M12*P12*Q12 -> 0.15274686 | S12: =O12-R12 -> 27.532622 | T12: =IF(O12=0,0,S12/O12) -> 0.99448276
A13: 9 | B13: =EDATE(Assumptions!$C$5,A13-1) -> 46508 | C13: =ROUNDUP(A13/12,0) -> 1 | D13: =INDEX('Market Expansion'!$B$21:$B$56,A13) -> 200 | E13: =INDEX(Seasonality!$E$8:$E$19,MONTH(B13)) -> 0.47619048 | F13: =Assumptions!$C$16*(1+Assumptions!$C$17)^((A13-1)/12) -> 0.027441335 | G13: =D13*F13*E13 -> 2.6134605 | H13: =G13*Assumptions!$C$18 -> 1.0453842 | I13: =H13*Assumptions!$C$19 -> 0.18816915 | J13: =M12*Assumptions!$C$24 -> 0.014320018 | K13: 0 | L13: =I13+J13+K13 -> 0.20248917 | M13: =L13+M12*(1-Assumptions!$C$23) -> 0.79438326 | N13: =IF(A13>=Assumptions!$C$11,Assumptions!$C$12,Assumptions!$C$10) -> 29 | O13: =M13*N13 -> 23.037115 | P13: =Assumptions!$C$29 -> 10 | Q13: =Assumptions!$C$30 -> 0.016 | R13: =M13*P13*Q13 -> 0.12710132 | S13: =O13-R13 -> 22.910013 | T13: =IF(O13=0,0,S13/O13) -> 0.99448276
A14: 10 | B14: =EDATE(Assumptions!$C$5,A14-1) -> 46539 | C14: =ROUNDUP(A14/12,0) -> 1 | D14: =INDEX('Market Expansion'!$B$21:$B$56,A14) -> 200 | E14: =INDEX(Seasonality!$E$8:$E$19,MONTH(B14)) -> 0.66666667 | F14: =Assumptions!$C$16*(1+Assumptions!$C$17)^((A14-1)/12) -> 0.027762808 | G14: =D14*F14*E14 -> 3.7017077 | H14: =G14*Assumptions!$C$18 -> 1.4806831 | I14: =H14*Assumptions!$C$19 -> 0.26652296 | J14: =M13*Assumptions!$C$24 -> 0.011915749 | K14: 0 | L14: =I14+J14+K14 -> 0.27843871 | M14: =L14+M13*(1-Assumptions!$C$23) -> 0.77095633 | N14: =IF(A14>=Assumptions!$C$11,Assumptions!$C$12,Assumptions!$C$10) -> 29 | O14: =M14*N14 -> 22.357734 | P14: =Assumptions!$C$29 -> 10 | Q14: =Assumptions!$C$30 -> 0.016 | R14: =M14*P14*Q14 -> 0.12335301 | S14: =O14-R14 -> 22.23438 | T14: =IF(O14=0,0,S14/O14) -> 0.99448276
A15: 11 | B15: =EDATE(Assumptions!$C$5,A15-1) -> 46569 | C15: =ROUNDUP(A15/12,0) -> 1 | D15: =INDEX('Market Expansion'!$B$21:$B$56,A15) -> 200 | E15: =INDEX(Seasonality!$E$8:$E$19,MONTH(B15)) -> 0.95238095 | F15: =Assumptions!$C$16*(1+Assumptions!$C$17)^((A15-1)/12) -> 0.028088047 | G15: =D15*F15*E15 -> 5.3501042 | H15: =G15*Assumptions!$C$18 -> 2.1400417 | I15: =H15*Assumptions!$C$19 -> 0.3852075 | J15: =M14*Assumptions!$C$24 -> 0.011564345 | K15: 0 | L15: =I15+J15+K15 -> 0.39677185 | M15: =L15+M14*(1-Assumptions!$C$23) -> 0.87476477 | N15: =IF(A15>=Assumptions!$C$11,Assumptions!$C$12,Assumptions!$C$10) -> 29 | O15: =M15*N15 -> 25.368178 | P15: =Assumptions!$C$29 -> 10 | Q15: =Assumptions!$C$30 -> 0.016 | R15: =M15*P15*Q15 -> 0.13996236 | S15: =O15-R15 -> 25.228216 | T15: =IF(O15=0,0,S15/O15) -> 0.99448276
A16: 12 | B16: =EDATE(Assumptions!$C$5,A16-1) -> 46600 | C16: =ROUNDUP(A16/12,0) -> 1 | D16: =INDEX('Market Expansion'!$B$21:$B$56,A16) -> 200 | E16: =INDEX(Seasonality!$E$8:$E$19,MONTH(B16)) -> 1.3333333 | F16: =Assumptions!$C$16*(1+Assumptions!$C$17)^((A16-1)/12) -> 0.028417096 | G16: =D16*F16*E16 -> 7.5778923 | H16: =G16*Assumptions!$C$18 -> 3.0311569 | I16: =H16*Assumptions!$C$19 -> 0.54560824 | J16: =M15*Assumptions!$C$24 -> 0.013121472 | K16: 0 | L16: =I16+J16+K16 -> 0.55872972 | M16: =L16+M15*(1-Assumptions!$C$23) -> 1.1010839 | N16: =IF(A16>=Assumptions!$C$11,Assumptions!$C$12,Assumptions!$C$10) -> 29 | O16: =M16*N16 -> 31.931432 | P16: =Assumptions!$C$29 -> 10 | Q16: =Assumptions!$C$30 -> 0.016 | R16: =M16*P16*Q16 -> 0.17617342 | S16: =O16-R16 -> 31.755259 | T16: =IF(O16=0,0,S16/O16) -> 0.99448276
A17: 13 | B17: =EDATE(Assumptions!$C$5,A17-1) -> 46631 | C17: =ROUNDUP(A17/12,0) -> 2 | D17: =INDEX('Market Expansion'!$B$21:$B$56,A17) -> 5000 | E17: =INDEX(Seasonality!$E$8:$E$19,MONTH(B17)) -> 1.7142857 | F17: =Assumptions!$C$16*(1+Assumptions!$C$17)^((A17-1)/12) -> 0.02875 | G17: =D17*F17*E17 -> 246.42857 | H17: =G17*Assumptions!$C$18 -> 98.571429 | I17: =H17*Assumptions!$C$19 -> 17.742857 | J17: =M16*Assumptions!$C$24 -> 0.016516258 | K17: =M5*Assumptions!$C$25 -> 0.037028571 | L17: =I17+J17+K17 -> 17.796402 | M17: =L17+M16*(1-Assumptions!$C$23) -> 18.479074 | N17: =IF(A17>=Assumptions!$C$11,Assumptions!$C$12,Assumptions!$C$10) -> 29 | O17: =M17*N17 -> 535.89315 | P17: =Assumptions!$C$29 -> 10 | Q17: =Assumptions!$C$30 -> 0.016 | R17: =M17*P17*Q17 -> 2.9566518 | S17: =O17-R17 -> 532.93649 | T17: =IF(O17=0,0,S17/O17) -> 0.99448276
A18: 14 | B18: =EDATE(Assumptions!$C$5,A18-1) -> 46661 | C18: =ROUNDUP(A18/12,0) -> 2 | D18: =INDEX('Market Expansion'!$B$21:$B$56,A18) -> 5000 | E18: =INDEX(Seasonality!$E$8:$E$19,MONTH(B18)) -> 1.5238095 | F18: =Assumptions!$C$16*(1+Assumptions!$C$17)^((A18-1)/12) -> 0.029086804 | G18: =D18*F18*E18 -> 221.61374 | H18: =G18*Assumptions!$C$18 -> 88.645497 | I18: =H18*Assumptions!$C$19 -> 15.95619 | J18: =M17*Assumptions!$C$24 -> 0.27718611 | K18: =M6*Assumptions!$C$25 -> 0.056813017 | L18: =I18+J18+K18 -> 16.290189 | M18: =L18+M17*(1-Assumptions!$C$23) -> 27.747215 | N18: =IF(A18>=Assumptions!$C$11,Assumptions!$C$12,Assumptions!$C$10) -> 29 | O18: =M18*N18 -> 804.66922 | P18: =Assumptions!$C$29 -> 10 | Q18: =Assumptions!$C$30 -> 0.016 | R18: =M18*P18*Q18 -> 4.4395543 | S18: =O18-R18 -> 800.22967 | T18: =IF(O18=0,0,S18/O18) -> 0.99448276
A19: 15 | B19: =EDATE(Assumptions!$C$5,A19-1) -> 46692 | C19: =ROUNDUP(A19/12,0) -> 2 | D19: =INDEX('Market Expansion'!$B$21:$B$56,A19) -> 5000 | E19: =INDEX(Seasonality!$E$8:$E$19,MONTH(B19)) -> 0.95238095 | F19: =Assumptions!$C$16*(1+Assumptions!$C$17)^((A19-1)/12) -> 0.029427553 | G19: =D19*F19*E19 -> 140.13121 | H19: =G19*Assumptions!$C$18 -> 56.052483 | I19: =H19*Assumptions!$C$19 -> 10.089447 | J19: =M18*Assumptions!$C$24 -> 0.41620822 | K19: =M7*Assumptions!$C$25 -> 0.057132503 | L19: =I19+J19+K19 -> 10.562788 | M19: =L19+M18*(1-Assumptions!$C$23) -> 27.766061 | N19: =IF(A19>=Assumptions!$C$11,Assumptions!$C$12,Assumptions!$C$10) -> 29 | O19: =M19*N19 -> 805.21576 | P19: =Assumptions!$C$29 -> 10 | Q19: =Assumptions!$C$30 -> 0.016 | R19: =M19*P19*Q19 -> 4.4425697 | S19: =O19-R19 -> 800.77319 | T19: =IF(O19=0,0,S19/O19) -> 0.99448276
A20: 16 | B20: =EDATE(Assumptions!$C$5,A20-1) -> 46722 | C20: =ROUNDUP(A20/12,0) -> 2 | D20: =INDEX('Market Expansion'!$B$21:$B$56,A20) -> 5000 | E20: =INDEX(Seasonality!$E$8:$E$19,MONTH(B20)) -> 0.57142857 | F20: =Assumptions!$C$16*(1+Assumptions!$C$17)^((A20-1)/12) -> 0.029772295 | G20: =D20*F20*E20 -> 85.063699 | H20: =G20*Assumptions!$C$18 -> 34.02548 | I20: =H20*Assumptions!$C$19 -> 6.1245863 | J20: =M19*Assumptions!$C$24 -> 0.41649091 | K20: =M8*Assumptions!$C$25 -> 0.049060885 | L20: =I20+J20+K20 -> 6.5901381 | M20: =L20+M19*(1-Assumptions!$C$23) -> 23.805096 | N20: =IF(A20>=Assumptions!$C$11,Assumptions!$C$12,Assumptions!$C$10) -> 29 | O20: =M20*N20 -> 690.34778 | P20: =Assumptions!$C$29 -> 10 | Q20: =Assumptions!$C$30 -> 0.016 | R20: =M20*P20*Q20 -> 3.8088153 | S20: =O20-R20 -> 686.53896 | T20: =IF(O20=0,0,S20/O20) -> 0.99448276
A21: 17 | B21: =EDATE(Assumptions!$C$5,A21-1) -> 46753 | C21: =ROUNDUP(A21/12,0) -> 2 | D21: =INDEX('Market Expansion'!$B$21:$B$56,A21) -> 5000 | E21: =INDEX(Seasonality!$E$8:$E$19,MONTH(B21)) -> 0.85714286 | F21: =Assumptions!$C$16*(1+Assumptions!$C$17)^((A21-1)/12) -> 0.030121075 | G21: =D21*F21*E21 -> 129.09032 | H21: =G21*Assumptions!$C$18 -> 51.636128 | I21: =H21*Assumptions!$C$19 -> 9.294503 | J21: =M20*Assumptions!$C$24 -> 0.35707644 | K21: =M9*Assumptions!$C$25 -> 0.050550885 | L21: =I21+J21+K21 -> 9.7021304 | M21: =L21+M20*(1-Assumptions!$C$23) -> 24.46129 | N21: =IF(A21>=Assumptions!$C$11,Assumptions!$C$12,Assumptions!$C$10) -> 29 | O21: =M21*N21 -> 709.3774 | P21: =Assumptions!$C$29 -> 10 | Q21: =Assumptions!$C$30 -> 0.016 | R21: =M21*P21*Q21 -> 3.9138064 | S21: =O21-R21 -> 705.46359 | T21: =IF(O21=0,0,S21/O21) -> 0.99448276
A22: 18 | B22: =EDATE(Assumptions!$C$5,A22-1) -> 46784 | C22: =ROUNDUP(A22/12,0) -> 2 | D22: =INDEX('Market Expansion'!$B$21:$B$56,A22) -> 5000 | E22: =INDEX(Seasonality!$E$8:$E$19,MONTH(B22)) -> 1.047619 | F22: =Assumptions!$C$16*(1+Assumptions!$C$17)^((A22-1)/12) -> 0.030473941 | G22: =D22*F22*E22 -> 159.6254 | H22: =G22*Assumptions!$C$18 -> 63.850161 | I22: =H22*Assumptions!$C$19 -> 11.493029 | J22: =M21*Assumptions!$C$24 -> 0.36691935 | K22: =M10*Assumptions!$C$25 -> 0.056085264 | L22: =I22+J22+K22 -> 11.916034 | M22: =L22+M21*(1-Assumptions!$C$23) -> 27.082033 | N22: =IF(A22>=Assumptions!$C$11,Assumptions!$C$12,Assumptions!$C$10) -> 29 | O22: =M22*N22 -> 785.37896 | P22: =Assumptions!$C$29 -> 10 | Q22: =Assumptions!$C$30 -> 0.016 | R22: =M22*P22*Q22 -> 4.3331253 | S22: =O22-R22 -> 781.04584 | T22: =IF(O22=0,0,S22/O22) -> 0.99448276
A23: 19 | B23: =EDATE(Assumptions!$C$5,A23-1) -> 46813 | C23: =ROUNDUP(A23/12,0) -> 2 | D23: =INDEX('Market Expansion'!$B$21:$B$56,A23) -> 5000 | E23: =INDEX(Seasonality!$E$8:$E$19,MONTH(B23)) -> 1.1428571 | F23: =Assumptions!$C$16*(1+Assumptions!$C$17)^((A23-1)/12) -> 0.03083094 | G23: =D23*F23*E23 -> 176.1768 | H23: =G23*Assumptions!$C$18 -> 70.470721 | I23: =H23*Assumptions!$C$19 -> 12.68473 | J23: =M22*Assumptions!$C$24 -> 0.4062305 | K23: =M11*Assumptions!$C$25 -> 0.062086622 | L23: =I23+J23+K23 -> 13.153047 | M23: =L23+M22*(1-Assumptions!$C$23) -> 29.943907 | N23: =IF(A23>=Assumptions!$C$11,Assumptions!$C$12,Assumptions!$C$10) -> 29 | O23: =M23*N23 -> 868.37331 | P23: =Assumptions!$C$29 -> 10 | Q23: =Assumptions!$C$30 -> 0.016 | R23: =M23*P23*Q23 -> 4.7910252 | S23: =O23-R23 -> 863.58229 | T23: =IF(O23=0,0,S23/O23) -> 0.99448276
A24: 20 | B24: =EDATE(Assumptions!$C$5,A24-1) -> 46844 | C24: =ROUNDUP(A24/12,0) -> 2 | D24: =INDEX('Market Expansion'!$B$21:$B$56,A24) -> 5000 | E24: =INDEX(Seasonality!$E$8:$E$19,MONTH(B24)) -> 0.76190476 | F24: =Assumptions!$C$16*(1+Assumptions!$C$17)^((A24-1)/12) -> 0.031192122 | G24: =D24*F24*E24 -> 118.82713 | H24: =G24*Assumptions!$C$18 -> 47.530853 | I24: =H24*Assumptions!$C$19 -> 8.5555535 | J24: =M23*Assumptions!$C$24 -> 0.44915861 | K24: =M12*Assumptions!$C$25 -> 0.057280073 | L24: =I24+J24+K24 -> 9.0619922 | M24: =L24+M23*(1-Assumptions!$C$23) -> 27.627215 | N24: =IF(A24>=Assumptions!$C$11,Assumptions!$C$12,Assumptions!$C$10) -> 29 | O24: =M24*N24 -> 801.18923 | P24: =Assumptions!$C$29 -> 10 | Q24: =Assumptions!$C$30 -> 0.016 | R24: =M24*P24*Q24 -> 4.4203544 | S24: =O24-R24 -> 796.76887 | T24: =IF(O24=0,0,S24/O24) -> 0.99448276
A25: 21 | B25: =EDATE(Assumptions!$C$5,A25-1) -> 46874 | C25: =ROUNDUP(A25/12,0) -> 2 | D25: =INDEX('Market Expansion'!$B$21:$B$56,A25) -> 5000 | E25: =INDEX(Seasonality!$E$8:$E$19,MONTH(B25)) -> 0.47619048 | F25: =Assumptions!$C$16*(1+Assumptions!$C$17)^((A25-1)/12) -> 0.031557535 | G25: =D25*F25*E25 -> 75.136989 | H25: =G25*Assumptions!$C$18 -> 30.054795 | I25: =H25*Assumptions!$C$19 -> 5.4098632 | J25: =M24*Assumptions!$C$24 -> 0.41440822 | K25: =M13*Assumptions!$C$25 -> 0.047662996 | L25: =I25+J25+K25 -> 5.8719344 | M25: =L25+M24*(1-Assumptions!$C$23) -> 23.000808 | N25: =IF(A25>=Assumptions!$C$11,Assumptions!$C$12,Assumptions!$C$10) -> 29 | O25: =M25*N25 -> 667.02342 | P25: =Assumptions!$C$29 -> 10 | Q25: =Assumptions!$C$30 -> 0.016 | R25: =M25*P25*Q25 -> 3.6801292 | S25: =O25-R25 -> 663.34329 | T25: =IF(O25=0,0,S25/O25) -> 0.99448276
A26: 22 | B26: =EDATE(Assumptions!$C$5,A26-1) -> 46905 | C26: =ROUNDUP(A26/12,0) -> 2 | D26: =INDEX('Market Expansion'!$B$21:$B$56,A26) -> 5000 | E26: =INDEX(Seasonality!$E$8:$E$19,MONTH(B26)) -> 0.66666667 | F26: =Assumptions!$C$16*(1+Assumptions!$C$17)^((A26-1)/12) -> 0.031927229 | G26: =D26*F26*E26 -> 106.4241 | H26: =G26*Assumptions!$C$18 -> 42.569639 | I26: =H26*Assumptions!$C$19 -> 7.662535 | J26: =M25*Assumptions!$C$24 -> 0.34501211 | K26: =M14*Assumptions!$C$25 -> 0.04625738 | L26: =I26+J26+K26 -> 8.0538045 | M26: =L26+M25*(1-Assumptions!$C$23) -> 22.314305 | N26: =IF(A26>=Assumptions!$C$11,Assumptions!$C$12,Assumptions!$C$10) -> 29 | O26: =M26*N26 -> 647.11485 | P26: =Assumptions!$C$29 -> 10 | Q26: =Assumptions!$C$30 -> 0.016 | R26: =M26*P26*Q26 -> 3.5702888 | S26: =O26-R26 -> 643.54456 | T26: =IF(O26=0,0,S26/O26) -> 0.99448276
A27: 23 | B27: =EDATE(Assumptions!$C$5,A27-1) -> 46935 | C27: =ROUNDUP(A27/12,0) -> 2 | D27: =INDEX('Market Expansion'!$B$21:$B$56,A27) -> 5000 | E27: =INDEX(Seasonality!$E$8:$E$19,MONTH(B27)) -> 0.95238095 | F27: =Assumptions!$C$16*(1+Assumptions!$C$17)^((A27-1)/12) -> 0.032301254 | G27: =D27*F27*E27 -> 153.8155 | H27: =G27*Assumptions!$C$18 -> 61.526198 | I27: =H27*Assumptions!$C$19 -> 11.074716 | J27: =M26*Assumptions!$C$24 -> 0.33471458 | K27: =M15*Assumptions!$C$25 -> 0.052485886 | L27: =I27+J27+K27 -> 11.461916 | M27: =L27+M26*(1-Assumptions!$C$23) -> 25.296785 | N27: =IF(A27>=Assumptions!$C$11,Assumptions!$C$12,Assumptions!$C$10) -> 29 | O27: =M27*N27 -> 733.60677 | P27: =Assumptions!$C$29 -> 10 | Q27: =Assumptions!$C$30 -> 0.016 | R27: =M27*P27*Q27 -> 4.0474857 | S27: =O27-R27 -> 729.55929 | T27: =IF(O27=0,0,S27/O27) -> 0.99448276
A28: 24 | B28: =EDATE(Assumptions!$C$5,A28-1) -> 46966 | C28: =ROUNDUP(A28/12,0) -> 2 | D28: =INDEX('Market Expansion'!$B$21:$B$56,A28) -> 5000 | E28: =INDEX(Seasonality!$E$8:$E$19,MONTH(B28)) -> 1.3333333 | F28: =Assumptions!$C$16*(1+Assumptions!$C$17)^((A28-1)/12) -> 0.03267966 | G28: =D28*F28*E28 -> 217.8644 | H28: =G28*Assumptions!$C$18 -> 87.145761 | I28: =H28*Assumptions!$C$19 -> 15.686237 | J28: =M27*Assumptions!$C$24 -> 0.37945178 | K28: =M16*Assumptions!$C$25 -> 0.066065032 | L28: =I28+J28+K28 -> 16.131754 | M28: =L28+M27*(1-Assumptions!$C$23) -> 31.815761 | N28: =IF(A28>=Assumptions!$C$11,Assumptions!$C$12,Assumptions!$C$10) -> 29 | O28: =M28*N28 -> 922.65706 | P28: =Assumptions!$C$29 -> 10 | Q28: =Assumptions!$C$30 -> 0.016 | R28: =M28*P28*Q28 -> 5.0905217 | S28: =O28-R28 -> 917.56654 | T28: =IF(O28=0,0,S28/O28) -> 0.99448276
... A40: 36 | B40: =EDATE(Assumptions!$C$5,A40-1) -> 47331 | C40: =ROUNDUP(A40/12,0) -> 3 | D40: =INDEX('Market Expansion'!$B$21:$B$56,A40) -> 25000 | E40: =INDEX(Seasonality!$E$8:$E$19,MONTH(B40)) -> 1.3333333 | F40: =Assumptions!$C$16*(1+Assumptions!$C$17)^((A40-1)/12) -> 0.03758161 | G40: =D40*F40*E40 -> 1252.7203 | H40: =G40*Assumptions!$C$18 -> 501.08813 | I40: =H40*Assumptions!$C$19 -> 90.195863 | J40: =M39*Assumptions!$C$24 -> 2.0416484 | K40: =M28*Assumptions!$C$25 -> 1.9089456 | L40: =I40+J40+K40 -> 94.146457 | M40: =L40+M39*(1-Assumptions!$C$23) -> 178.53459 | N40: =IF(A40>=Assumptions!$C$11,Assumptions!$C$12,Assumptions!$C$10) -> 29 | O40: =M40*N40 -> 5177.5032 | P40: =Assumptions!$C$29 -> 10 | Q40: =Assumptions!$C$30 -> 0.016 | R40: =M40*P40*Q40 -> 28.565535 | S40: =O40-R40 -> 5148.9376 | T40: =IF(O40=0,0,S40/O40) -> 0.99448276

Sheet Forecast - Base
A1: 36-Month Forecast — Base Case
A2: Cohort build: Leads → Free → Paid → Active, with churn, referral, and repeat-user loops. All dollar figures illustrative.
A4: Month # | B4: Calendar Month | C4: Year | D4: Addressable Pool | E4: Seasonality Multiplier | F4: Effective Awareness Rate | G4: Leads | H4: Free Signups | I4: Paid Conversions | J4: Referral Subs | K4: Returning Subs | L4: Total New Paying Subs | M4: Active Subs | N4: Monthly Price | O4: Monthly Revenue | P4: Cases / User | Q4: Cost / Case | R4: Monthly COGS | S4: Gross Profit | T4: Gross Margin %
A5: 1 | B5: =EDATE(Assumptions!$C$5,A5-1) -> 46266 | C5: =ROUNDUP(A5/12,0) -> 1 | D5: =INDEX('Market Expansion'!$C$21:$C$56,A5) -> 200 | E5: =INDEX(Seasonality!$E$8:$E$19,MONTH(B5)) -> 1.7142857 | F5: =Assumptions!$D$16*(1+Assumptions!$D$17)^((A5-1)/12) -> 0.03 | G5: =D5*F5*E5 -> 10.285714 | H5: =G5*Assumptions!$D$18 -> 5.1428571 | I5: =H5*Assumptions!$D$19 -> 1.0285714 | J5: 0 | K5: 0 | L5: =I5+J5+K5 -> 1.0285714 | M5: =L5 -> 1.0285714 | N5: =IF(A5>=Assumptions!$D$11,Assumptions!$D$12,Assumptions!$D$10) -> 29 | O5: =M5*N5 -> 29.828571 | P5: =Assumptions!$D$29 -> 10 | Q5: =Assumptions!$D$30 -> 0.016 | R5: =M5*P5*Q5 -> 0.16457143 | S5: =O5-R5 -> 29.664 | T5: =IF(O5=0,0,S5/O5) -> 0.99448276
A6: 2 | B6: =EDATE(Assumptions!$C$5,A6-1) -> 46296 | C6: =ROUNDUP(A6/12,0) -> 1 | D6: =INDEX('Market Expansion'!$C$21:$C$56,A6) -> 200 | E6: =INDEX(Seasonality!$E$8:$E$19,MONTH(B6)) -> 1.5238095 | F6: =Assumptions!$D$16*(1+Assumptions!$D$17)^((A6-1)/12) -> 0.030459284 | G6: =D6*F6*E6 -> 9.2828294 | H6: =G6*Assumptions!$D$18 -> 4.6414147 | I6: =H6*Assumptions!$D$19 -> 0.92828294 | J6: =M5*Assumptions!$D$24 -> 0.020571429 | K6: 0 | L6: =I6+J6+K6 -> 0.94885437 | M6: =L6+M5*(1-Assumptions!$D$23) -> 1.6379972 | N6: =IF(A6>=Assumptions!$D$11,Assumptions!$D$12,Assumptions!$D$10) -> 29 | O6: =M6*N6 -> 47.50192 | P6: =Assumptions!$D$29 -> 10 | Q6: =Assumptions!$D$30 -> 0.016 | R6: =M6*P6*Q6 -> 0.26207956 | S6: =O6-R6 -> 47.23984 | T6: =IF(O6=0,0,S6/O6) -> 0.99448276
A7: 3 | B7: =EDATE(Assumptions!$C$5,A7-1) -> 46327 | C7: =ROUNDUP(A7/12,0) -> 1 | D7: =INDEX('Market Expansion'!$C$21:$C$56,A7) -> 200 | E7: =INDEX(Seasonality!$E$8:$E$19,MONTH(B7)) -> 0.95238095 | F7: =Assumptions!$D$16*(1+Assumptions!$D$17)^((A7-1)/12) -> 0.0309256 | G7: =D7*F7*E7 -> 5.8905904 | H7: =G7*Assumptions!$D$18 -> 2.9452952 | I7: =H7*Assumptions!$D$19 -> 0.58905904 | J7: =M6*Assumptions!$D$24 -> 0.032759945 | K7: 0 | L7: =I7+J7+K7 -> 0.62181899 | M7: =L7+M6*(1-Assumptions!$D$23) -> 1.7192771 | N7: =IF(A7>=Assumptions!$D$11,Assumptions!$D$12,Assumptions!$D$10) -> 29 | O7: =M7*N7 -> 49.859037 | P7: =Assumptions!$D$29 -> 10 | Q7: =Assumptions!$D$30 -> 0.016 | R7: =M7*P7*Q7 -> 0.27508434 | S7: =O7-R7 -> 49.583952 | T7: =IF(O7=0,0,S7/O7) -> 0.99448276
A8: 4 | B8: =EDATE(Assumptions!$C$5,A8-1) -> 46357 | C8: =ROUNDUP(A8/12,0) -> 1 | D8: =INDEX('Market Expansion'!$C$21:$C$56,A8) -> 200 | E8: =INDEX(Seasonality!$E$8:$E$19,MONTH(B8)) -> 0.57142857 | F8: =Assumptions!$D$16*(1+Assumptions!$D$17)^((A8-1)/12) -> 0.031399054 | G8: =D8*F8*E8 -> 3.5884633 | H8: =G8*Assumptions!$D$18 -> 1.7942317 | I8: =H8*Assumptions!$D$19 -> 0.35884633 | J8: =M7*Assumptions!$D$24 -> 0.034385543 | K8: 0 | L8: =I8+J8+K8 -> 0.39323188 | M8: =L8+M7*(1-Assumptions!$D$23) -> 1.5451476 | N8: =IF(A8>=Assumptions!$D$11,Assumptions!$D$12,Assumptions!$D$10) -> 29 | O8: =M8*N8 -> 44.809279 | P8: =Assumptions!$D$29 -> 10 | Q8: =Assumptions!$D$30 -> 0.016 | R8: =M8*P8*Q8 -> 0.24722361 | S8: =O8-R8 -> 44.562055 | T8: =IF(O8=0,0,S8/O8) -> 0.99448276
A9: 5 | B9: =EDATE(Assumptions!$C$5,A9-1) -> 46388 | C9: =ROUNDUP(A9/12,0) -> 1 | D9: =INDEX('Market Expansion'!$C$21:$C$56,A9) -> 200 | E9: =INDEX(Seasonality!$E$8:$E$19,MONTH(B9)) -> 0.85714286 | F9: =Assumptions!$D$16*(1+Assumptions!$D$17)^((A9-1)/12) -> 0.031879757 | G9: =D9*F9*E9 -> 5.4651012 | H9: =G9*Assumptions!$D$18 -> 2.7325506 | I9: =H9*Assumptions!$D$19 -> 0.54651012 | J9: =M8*Assumptions!$D$24 -> 0.030902951 | K9: 0 | L9: =I9+J9+K9 -> 0.57741307 | M9: =L9+M8*(1-Assumptions!$D$23) -> 1.6126619 | N9: =IF(A9>=Assumptions!$D$11,Assumptions!$D$12,Assumptions!$D$10) -> 29 | O9: =M9*N9 -> 46.767196 | P9: =Assumptions!$D$29 -> 10 | Q9: =Assumptions!$D$30 -> 0.016 | R9: =M9*P9*Q9 -> 0.25802591 | S9: =O9-R9 -> 46.50917 | T9: =IF(O9=0,0,S9/O9) -> 0.99448276
A10: 6 | B10: =EDATE(Assumptions!$C$5,A10-1) -> 46419 | C10: =ROUNDUP(A10/12,0) -> 1 | D10: =INDEX('Market Expansion'!$C$21:$C$56,A10) -> 200 | E10: =INDEX(Seasonality!$E$8:$E$19,MONTH(B10)) -> 1.047619 | F10: =Assumptions!$D$16*(1+Assumptions!$D$17)^((A10-1)/12) -> 0.032367819 | G10: =D10*F10*E10 -> 6.7818288 | H10: =G10*Assumptions!$D$18 -> 3.3909144 | I10: =H10*Assumptions!$D$19 -> 0.67818288 | J10: =M9*Assumptions!$D$24 -> 0.032253239 | K10: 0 | L10: =I10+J10+K10 -> 0.71043612 | M10: =L10+M9*(1-Assumptions!$D$23) -> 1.7909196 | N10: =IF(A10>=Assumptions!$D$11,Assumptions!$D$12,Assumptions!$D$10) -> 29 | O10: =M10*N10 -> 51.936669 | P10: =Assumptions!$D$29 -> 10 | Q10: =Assumptions!$D$30 -> 0.016 | R10: =M10*P10*Q10 -> 0.28654714 | S10: =O10-R10 -> 51.650122 | T10: =IF(O10=0,0,S10/O10) -> 0.99448276
A11: 7 | B11: =EDATE(Assumptions!$C$5,A11-1) -> 46447 | C11: =ROUNDUP(A11/12,0) -> 1 | D11: =INDEX('Market Expansion'!$C$21:$C$56,A11) -> 5000 | E11: =INDEX(Seasonality!$E$8:$E$19,MONTH(B11)) -> 1.1428571 | F11: =Assumptions!$D$16*(1+Assumptions!$D$17)^((A11-1)/12) -> 0.032863353 | G11: =D11*F11*E11 -> 187.79059 | H11: =G11*Assumptions!$D$18 -> 93.895296 | I11: =H11*Assumptions!$D$19 -> 18.779059 | J11: =M10*Assumptions!$D$24 -> 0.035818392 | K11: 0 | L11: =I11+J11+K11 -> 18.814878 | M11: =L11+M10*(1-Assumptions!$D$23) -> 20.014794 | N11: =IF(A11>=Assumptions!$D$11,Assumptions!$D$12,Assumptions!$D$10) -> 29 | O11: =M11*N11 -> 580.42902 | P11: =Assumptions!$D$29 -> 10 | Q11: =Assumptions!$D$30 -> 0.016 | R11: =M11*P11*Q11 -> 3.202367 | S11: =O11-R11 -> 577.22665 | T11: =IF(O11=0,0,S11/O11) -> 0.99448276
A12: 8 | B12: =EDATE(Assumptions!$C$5,A12-1) -> 46478 | C12: =ROUNDUP(A12/12,0) -> 1 | D12: =INDEX('Market Expansion'!$C$21:$C$56,A12) -> 5000 | E12: =INDEX(Seasonality!$E$8:$E$19,MONTH(B12)) -> 0.76190476 | F12: =Assumptions!$D$16*(1+Assumptions!$D$17)^((A12-1)/12) -> 0.033366474 | G12: =D12*F12*E12 -> 127.11038 | H12: =G12*Assumptions!$D$18 -> 63.555189 | I12: =H12*Assumptions!$D$19 -> 12.711038 | J12: =M11*Assumptions!$D$24 -> 0.40029587 | K12: 0 | L12: =I12+J12+K12 -> 13.111334 | M12: =L12+M11*(1-Assumptions!$D$23) -> 26.521245 | N12: =IF(A12>=Assumptions!$D$11,Assumptions!$D$12,Assumptions!$D$10) -> 29 | O12: =M12*N12 -> 769.11611 | P12: =Assumptions!$D$29 -> 10 | Q12: =Assumptions!$D$30 -> 0.016 | R12: =M12*P12*Q12 -> 4.2433993 | S12: =O12-R12 -> 764.87272 | T12: =IF(O12=0,0,S12/O12) -> 0.99448276
A13: 9 | B13: =EDATE(Assumptions!$C$5,A13-1) -> 46508 | C13: =ROUNDUP(A13/12,0) -> 1 | D13: =INDEX('Market Expansion'!$C$21:$C$56,A13) -> 5000 | E13: =INDEX(Seasonality!$E$8:$E$19,MONTH(B13)) -> 0.47619048 | F13: =Assumptions!$D$16*(1+Assumptions!$D$17)^((A13-1)/12) -> 0.033877297 | G13: =D13*F13*E13 -> 80.660231 | H13: =G13*Assumptions!$D$18 -> 40.330116 | I13: =H13*Assumptions!$D$19 -> 8.0660231 | J13: =M12*Assumptions!$D$24 -> 0.53042491 | K13: 0 | L13: =I13+J13+K13 -> 8.596448 | M13: =L13+M12*(1-Assumptions!$D$23) -> 26.365682 | N13: =IF(A13>=Assumptions!$D$11,Assumptions!$D$12,Assumptions!$D$10) -> 29 | O13: =M13*N13 -> 764.60479 | P13: =Assumptions!$D$29 -> 10 | Q13: =Assumptions!$D$30 -> 0.016 | R13: =M13*P13*Q13 -> 4.2185092 | S13: =O13-R13 -> 760.38628 | T13: =IF(O13=0,0,S13/O13) -> 0.99448276
A14: 10 | B14: =EDATE(Assumptions!$C$5,A14-1) -> 46539 | C14: =ROUNDUP(A14/12,0) -> 1 | D14: =INDEX('Market Expansion'!$C$21:$C$56,A14) -> 5000 | E14: =INDEX(Seasonality!$E$8:$E$19,MONTH(B14)) -> 0.66666667 | F14: =Assumptions!$D$16*(1+Assumptions!$D$17)^((A14-1)/12) -> 0.034395941 | G14: =D14*F14*E14 -> 114.65314 | H14: =G14*Assumptions!$D$18 -> 57.326568 | I14: =H14*Assumptions!$D$19 -> 11.465314 | J14: =M13*Assumptions!$D$24 -> 0.52731365 | K14: 0 | L14: =I14+J14+K14 -> 11.992627 | M14: =L14+M13*(1-Assumptions!$D$23) -> 29.657634 | N14: =IF(A14>=Assumptions!$D$11,Assumptions!$D$12,Assumptions!$D$10) -> 29 | O14: =M14*N14 -> 860.0714 | P14: =Assumptions!$D$29 -> 10 | Q14: =Assumptions!$D$30 -> 0.016 | R14: =M14*P14*Q14 -> 4.7452215 | S14: =O14-R14 -> 855.32617 | T14: =IF(O14=0,0,S14/O14) -> 0.99448276
A15: 11 | B15: =EDATE(Assumptions!$C$5,A15-1) -> 46569 | C15: =ROUNDUP(A15/12,0) -> 1 | D15: =INDEX('Market Expansion'!$C$21:$C$56,A15) -> 5000 | E15: =INDEX(Seasonality!$E$8:$E$19,MONTH(B15)) -> 0.95238095 | F15: =Assumptions!$D$16*(1+Assumptions!$D$17)^((A15-1)/12) -> 0.034922524 | G15: =D15*F15*E15 -> 166.29773 | H15: =G15*Assumptions!$D$18 -> 83.148867 | I15: =H15*Assumptions!$D$19 -> 16.629773 | J15: =M14*Assumptions!$D$24 -> 0.59315269 | K15: 0 | L15: =I15+J15+K15 -> 17.222926 | M15: =L15+M14*(1-Assumptions!$D$23) -> 37.093541 | N15: =IF(A15>=Assumptions!$D$11,Assumptions!$D$12,Assumptions!$D$10) -> 29 | O15: =M15*N15 -> 1075.7127 | P15: =Assumptions!$D$29 -> 10 | Q15: =Assumptions!$D$30 -> 0.016 | R15: =M15*P15*Q15 -> 5.9349666 | S15: =O15-R15 -> 1069.7777 | T15: =IF(O15=0,0,S15/O15) -> 0.99448276
A16: 12 | B16: =EDATE(Assumptions!$C$5,A16-1) -> 46600 | C16: =ROUNDUP(A16/12,0) -> 1 | D16: =INDEX('Market Expansion'!$C$21:$C$56,A16) -> 5000 | E16: =INDEX(Seasonality!$E$8:$E$19,MONTH(B16)) -> 1.3333333 | F16: =Assumptions!$D$16*(1+Assumptions!$D$17)^((A16-1)/12) -> 0.03545717 | G16: =D16*F16*E16 -> 236.38113 | H16: =G16*Assumptions!$D$18 -> 118.19057 | I16: =H16*Assumptions!$D$19 -> 23.638113 | J16: =M15*Assumptions!$D$24 -> 0.74187082 | K16: 0 | L16: =I16+J16+K16 -> 24.379984 | M16: =L16+M15*(1-Assumptions!$D$23) -> 49.232656 | N16: =IF(A16>=Assumptions!$D$11,Assumptions!$D$12,Assumptions!$D$10) -> 29 | O16: =M16*N16 -> 1427.747 | P16: =Assumptions!$D$29 -> 10 | Q16: =Assumptions!$D$30 -> 0.016 | R16: =M16*P16*Q16 -> 7.877225 | S16: =O16-R16 -> 1419.8698 | T16: =IF(O16=0,0,S16/O16) -> 0.99448276
A17: 13 | B17: =EDATE(Assumptions!$C$5,A17-1) -> 46631 | C17: =ROUNDUP(A17/12,0) -> 2 | D17: =INDEX('Market Expansion'!$C$21:$C$56,A17) -> 5000 | E17: =INDEX(Seasonality!$E$8:$E$19,MONTH(B17)) -> 1.7142857 | F17: =Assumptions!$D$16*(1+Assumptions!$D$17)^((A17-1)/12) -> 0.036 | G17: =D17*F17*E17 -> 308.57143 | H17: =G17*Assumptions!$D$18 -> 154.28571 | I17: =H17*Assumptions!$D$19 -> 30.857143 | J17: =M16*Assumptions!$D$24 -> 0.98465313 | K17: =M5*Assumptions!$D$25 -> 0.082285714 | L17: =I17+J17+K17 -> 31.924082 | M17: =L17+M16*(1-Assumptions!$D$23) -> 64.909961 | N17: =IF(A17>=Assumptions!$D$11,Assumptions!$D$12,Assumptions!$D$10) -> 29 | O17: =M17*N17 -> 1882.3889 | P17: =Assumptions!$D$29 -> 10 | Q17: =Assumptions!$D$30 -> 0.016 | R17: =M17*P17*Q17 -> 10.385594 | S17: =O17-R17 -> 1872.0033 | T17: =IF(O17=0,0,S17/O17) -> 0.99448276
A18: 14 | B18: =EDATE(Assumptions!$C$5,A18-1) -> 46661 | C18: =ROUNDUP(A18/12,0) -> 2 | D18: =INDEX('Market Expansion'!$C$21:$C$56,A18) -> 5000 | E18: =INDEX(Seasonality!$E$8:$E$19,MONTH(B18)) -> 1.5238095 | F18: =Assumptions!$D$16*(1+Assumptions!$D$17)^((A18-1)/12) -> 0.036551141 | G18: =D18*F18*E18 -> 278.48488 | H18: =G18*Assumptions!$D$18 -> 139.24244 | I18: =H18*Assumptions!$D$19 -> 27.848488 | J18: =M17*Assumptions!$D$24 -> 1.2981992 | K18: =M6*Assumptions!$D$25 -> 0.13103978 | L18: =I18+J18+K18 -> 29.277727 | M18: =L18+M17*(1-Assumptions!$D$23) -> 72.767402 | N18: =IF(A18>=Assumptions!$D$11,Assumptions!$D$12,Assumptions!$D$10) -> 29 | O18: =M18*N18 -> 2110.2546 | P18: =Assumptions!$D$29 -> 10 | Q18: =Assumptions!$D$30 -> 0.016 | R18: =M18*P18*Q18 -> 11.642784 | S18: =O18-R18 -> 2098.6119 | T18: =IF(O18=0,0,S18/O18) -> 0.99448276
A19: 15 | B19: =EDATE(Assumptions!$C$5,A19-1) -> 46692 | C19: =ROUNDUP(A19/12,0) -> 2 | D19: =INDEX('Market Expansion'!$C$21:$C$56,A19) -> 5000 | E19: =INDEX(Seasonality!$E$8:$E$19,MONTH(B19)) -> 0.95238095 | F19: =Assumptions!$D$16*(1+Assumptions!$D$17)^((A19-1)/12) -> 0.03711072 | G19: =D19*F19*E19 -> 176.71771 | H19: =G19*Assumptions!$D$18 -> 88.358856 | I19: =H19*Assumptions!$D$19 -> 17.671771 | J19: =M18*Assumptions!$D$24 -> 1.455348 | K19: =M7*Assumptions!$D$25 -> 0.13754217 | L19: =I19+J19+K19 -> 19.264661 | M19: =L19+M18*(1-Assumptions!$D$23) -> 68.01882 | N19: =IF(A19>=Assumptions!$D$11,Assumptions!$D$12,Assumptions!$D$10) -> 29 | O19: =M19*N19 -> 1972.5458 | P19: =Assumptions!$D$29 -> 10 | Q19: =Assumptions!$D$30 -> 0.016 | R19: =M19*P19*Q19 -> 10.883011 | S19: =O19-R19 -> 1961.6628 | T19: =IF(O19=0,0,S19/O19) -> 0.99448276
A20: 16 | B20: =EDATE(Assumptions!$C$5,A20-1) -> 46722 | C20: =ROUNDUP(A20/12,0) -> 2 | D20: =INDEX('Market Expansion'!$C$21:$C$56,A20) -> 25000 | E20: =INDEX(Seasonality!$E$8:$E$19,MONTH(B20)) -> 0.57142857 | F20: =Assumptions!$D$16*(1+Assumptions!$D$17)^((A20-1)/12) -> 0.037678865 | G20: =D20*F20*E20 -> 538.2695 | H20: =G20*Assumptions!$D$18 -> 269.13475 | I20: =H20*Assumptions!$D$19 -> 53.82695 | J20: =M19*Assumptions!$D$24 -> 1.3603764 | K20: =M8*Assumptions!$D$25 -> 0.1236118 | L20: =I20+J20+K20 -> 55.310938 | M20: =L20+M19*(1-Assumptions!$D$23) -> 100.88355 | N20: =IF(A20>=Assumptions!$D$11,Assumptions!$D$12,Assumptions!$D$10) -> 29 | O20: =M20*N20 -> 2925.6229 | P20: =Assumptions!$D$29 -> 10 | Q20: =Assumptions!$D$30 -> 0.016 | R20: =M20*P20*Q20 -> 16.141368 | S20: =O20-R20 -> 2909.4815 | T20: =IF(O20=0,0,S20/O20) -> 0.99448276
A21: 17 | B21: =EDATE(Assumptions!$C$5,A21-1) -> 46753 | C21: =ROUNDUP(A21/12,0) -> 2 | D21: =INDEX('Market Expansion'!$C$21:$C$56,A21) -> 25000 | E21: =INDEX(Seasonality!$E$8:$E$19,MONTH(B21)) -> 0.85714286 | F21: =Assumptions!$D$16*(1+Assumptions!$D$17)^((A21-1)/12) -> 0.038255708 | G21: =D21*F21*E21 -> 819.76518 | H21: =G21*Assumptions!$D$18 -> 409.88259 | I21: =H21*Assumptions!$D$19 -> 81.976518 | J21: =M20*Assumptions!$D$24 -> 2.017671 | K21: =M9*Assumptions!$D$25 -> 0.12901295 | L21: =I21+J21+K21 -> 84.123202 | M21: =L21+M20*(1-Assumptions!$D$23) -> 151.71518 | N21: =IF(A21>=Assumptions!$D$11,Assumptions!$D$12,Assumptions!$D$10) -> 29 | O21: =M21*N21 -> 4399.7402 | P21: =Assumptions!$D$29 -> 10 | Q21: =Assumptions!$D$30 -> 0.016 | R21: =M21*P21*Q21 -> 24.274429 | S21: =O21-R21 -> 4375.4658 | T21: =IF(O21=0,0,S21/O21) -> 0.99448276
A22: 18 | B22: =EDATE(Assumptions!$C$5,A22-1) -> 46784 | C22: =ROUNDUP(A22/12,0) -> 2 | D22: =INDEX('Market Expansion'!$C$21:$C$56,A22) -> 25000 | E22: =INDEX(Seasonality!$E$8:$E$19,MONTH(B22)) -> 1.047619 | F22: =Assumptions!$D$16*(1+Assumptions!$D$17)^((A22-1)/12) -> 0.038841383 | G22: =D22*F22*E22 -> 1017.2743 | H22: =G22*Assumptions!$D$18 -> 508.63716 | I22: =H22*Assumptions!$D$19 -> 101.72743 | J22: =M21*Assumptions!$D$24 -> 3.0343036 | K22: =M10*Assumptions!$D$25 -> 0.14327357 | L22: =I22+J22+K22 -> 104.90501 | M22: =L22+M21*(1-Assumptions!$D$23) -> 206.55418 | N22: =IF(A22>=Assumptions!$D$11,Assumptions!$D$12,Assumptions!$D$10) -> 29 | O22: =M22*N22 -> 5990.0712 | P22: =Assumptions!$D$29 -> 10 | Q22: =Assumptions!$D$30 -> 0.016 | R22: =M22*P22*Q22 -> 33.048669 | S22: =O22-R22 -> 5957.0225 | T22: =IF(O22=0,0,S22/O22) -> 0.99448276
A23: 19 | B23: =EDATE(Assumptions!$C$5,A23-1) -> 46813 | C23: =ROUNDUP(A23/12,0) -> 2 | D23: =INDEX('Market Expansion'!$C$21:$C$56,A23) -> 25000 | E23: =INDEX(Seasonality!$E$8:$E$19,MONTH(B23)) -> 1.1428571 | F23: =Assumptions!$D$16*(1+Assumptions!$D$17)^((A23-1)/12) -> 0.039436024 | G23: =D23*F23*E23 -> 1126.7435 | H23: =G23*Assumptions!$D$18 -> 563.37177 | I23: =H23*Assumptions!$D$19 -> 112.67435 | J23: =M22*Assumptions!$D$24 -> 4.1310836 | K23: =M11*Assumptions!$D$25 -> 1.6011835 | L23: =I23+J23+K23 -> 118.40662 | M23: =L23+M22*(1-Assumptions!$D$23) -> 256.79792 | N23: =IF(A23>=Assumptions!$D$11,Assumptions!$D$12,Assumptions!$D$10) -> 29 | O23: =M23*N23 -> 7447.1397 | P23: =Assumptions!$D$29 -> 10 | Q23: =Assumptions!$D$30 -> 0.016 | R23: =M23*P23*Q23 -> 41.087667 | S23: =O23-R23 -> 7406.0521 | T23: =IF(O23=0,0,S23/O23) -> 0.99448276
A24: 20 | B24: =EDATE(Assumptions!$C$5,A24-1) -> 46844 | C24: =ROUNDUP(A24/12,0) -> 2 | D24: =INDEX('Market Expansion'!$C$21:$C$56,A24) -> 25000 | E24: =INDEX(Seasonality!$E$8:$E$19,MONTH(B24)) -> 0.76190476 | F24: =Assumptions!$D$16*(1+Assumptions!$D$17)^((A24-1)/12) -> 0.040039769 | G24: =D24*F24*E24 -> 762.66226 | H24: =G24*Assumptions!$D$18 -> 381.33113 | I24: =H24*Assumptions!$D$19 -> 76.266226 | J24: =M23*Assumptions!$D$24 -> 5.1359584 | K24: =M12*Assumptions!$D$25 -> 2.1216996 | L24: =I24+J24+K24 -> 83.523884 | M24: =L24+M23*(1-Assumptions!$D$23) -> 255.57849 | N24: =IF(A24>=Assumptions!$D$11,Assumptions!$D$12,Assumptions!$D$10) -> 29 | O24: =M24*N24 -> 7411.7763 | P24: =Assumptions!$D$29 -> 10 | Q24: =Assumptions!$D$30 -> 0.016 | R24: =M24*P24*Q24 -> 40.892559 | S24: =O24-R24 -> 7370.8837 | T24: =IF(O24=0,0,S24/O24) -> 0.99448276
A25: 21 | B25: =EDATE(Assumptions!$C$5,A25-1) -> 46874 | C25: =ROUNDUP(A25/12,0) -> 2 | D25: =INDEX('Market Expansion'!$C$21:$C$56,A25) -> 25000 | E25: =INDEX(Seasonality!$E$8:$E$19,MONTH(B25)) -> 0.47619048 | F25: =Assumptions!$D$16*(1+Assumptions!$D$17)^((A25-1)/12) -> 0.040652756 | G25: =D25*F25*E25 -> 483.96139 | H25: =G25*Assumptions!$D$18 -> 241.98069 | I25: =H25*Assumptions!$D$19 -> 48.396139 | J25: =M24*Assumptions!$D$24 -> 5.1115698 | K25: =M13*Assumptions!$D$25 -> 2.1092546 | L25: =I25+J25+K25 -> 55.616963 | M25: =L25+M24*(1-Assumptions!$D$23) -> 226.85455 | N25: =IF(A25>=Assumptions!$D$11,Assumptions!$D$12,Assumptions!$D$10) -> 29 | O25: =M25*N25 -> 6578.782 | P25: =Assumptions!$D$29 -> 10 | Q25: =Assumptions!$D$30 -> 0.016 | R25: =M25*P25*Q25 -> 36.296728 | S25: =O25-R25 -> 6542.4853 | T25: =IF(O25=0,0,S25/O25) -> 0.99448276
A26: 22 | B26: =EDATE(Assumptions!$C$5,A26-1) -> 46905 | C26: =ROUNDUP(A26/12,0) -> 2 | D26: =INDEX('Market Expansion'!$C$21:$C$56,A26) -> 25000 | E26: =INDEX(Seasonality!$E$8:$E$19,MONTH(B26)) -> 0.66666667 | F26: =Assumptions!$D$16*(1+Assumptions!$D$17)^((A26-1)/12) -> 0.041275129 | G26: =D26*F26*E26 -> 687.91881 | H26: =G26*Assumptions!$D$18 -> 343.95941 | I26: =H26*Assumptions!$D$19 -> 68.791881 | J26: =M25*Assumptions!$D$24 -> 4.5370911 | K26: =M14*Assumptions!$D$25 -> 2.3726107 | L26: =I26+J26+K26 -> 75.701583 | M26: =L26+M25*(1-Assumptions!$D$23) -> 227.69413 | N26: =IF(A26>=Assumptions!$D$11,Assumptions!$D$12,Assumptions!$D$10) -> 29 | O26: =M26*N26 -> 6603.1299 | P26: =Assumptions!$D$29 -> 10 | Q26: =Assumptions!$D$30 -> 0.016 | R26: =M26*P26*Q26 -> 36.431061 | S26: =O26-R26 -> 6566.6988 | T26: =IF(O26=0,0,S26/O26) -> 0.99448276
A27: 23 | B27: =EDATE(Assumptions!$C$5,A27-1) -> 46935 | C27: =ROUNDUP(A27/12,0) -> 2 | D27: =INDEX('Market Expansion'!$C$21:$C$56,A27) -> 25000 | E27: =INDEX(Seasonality!$E$8:$E$19,MONTH(B27)) -> 0.95238095 | F27: =Assumptions!$D$16*(1+Assumptions!$D$17)^((A27-1)/12) -> 0.041907029 | G27: =D27*F27*E27 -> 997.7864 | H27: =G27*Assumptions!$D$18 -> 498.8932 | I27: =H27*Assumptions!$D$19 -> 99.77864 | J27: =M26*Assumptions!$D$24 -> 4.5538827 | K27: =M15*Assumptions!$D$25 -> 2.9674833 | L27: =I27+J27+K27 -> 107.30001 | M27: =L27+M26*(1-Assumptions!$D$23) -> 259.85508 | N27: =IF(A27>=Assumptions!$D$11,Assumptions!$D$12,Assumptions!$D$10) -> 29 | O27: =M27*N27 -> 7535.7972 | P27: =Assumptions!$D$29 -> 10 | Q27: =Assumptions!$D$30 -> 0.016 | R27: =M27*P27*Q27 -> 41.576812 | S27: =O27-R27 -> 7494.2204 | T27: =IF(O27=0,0,S27/O27) -> 0.99448276
A28: 24 | B28: =EDATE(Assumptions!$C$5,A28-1) -> 46966 | C28: =ROUNDUP(A28/12,0) -> 2 | D28: =INDEX('Market Expansion'!$C$21:$C$56,A28) -> 25000 | E28: =INDEX(Seasonality!$E$8:$E$19,MONTH(B28)) -> 1.3333333 | F28: =Assumptions!$D$16*(1+Assumptions!$D$17)^((A28-1)/12) -> 0.042548603 | G28: =D28*F28*E28 -> 1418.2868 | H28: =G28*Assumptions!$D$18 -> 709.14339 | I28: =H28*Assumptions!$D$19 -> 141.82868 | J28: =M27*Assumptions!$D$24 -> 5.1971015 | K28: =M16*Assumptions!$D$25 -> 3.9386125 | L28: =I28+J28+K28 -> 150.96439 | M28: =L28+M27*(1-Assumptions!$D$23) -> 325.06729 | N28: =IF(A28>=Assumptions!$D$11,Assumptions!$D$12,Assumptions!$D$10) -> 29 | O28: =M28*N28 -> 9426.9515 | P28: =Assumptions!$D$29 -> 10 | Q28: =Assumptions!$D$30 -> 0.016 | R28: =M28*P28*Q28 -> 52.010767 | S28: =O28-R28 -> 9374.9407 | T28: =IF(O28=0,0,S28/O28) -> 0.99448276
... A40: 36 | B40: =EDATE(Assumptions!$C$5,A40-1) -> 47331 | C40: =ROUNDUP(A40/12,0) -> 3 | D40: =INDEX('Market Expansion'!$C$21:$C$56,A40) -> 50000 | E40: =INDEX(Seasonality!$E$8:$E$19,MONTH(B40)) -> 1.3333333 | F40: =Assumptions!$D$16*(1+Assumptions!$D$17)^((A40-1)/12) -> 0.051058324 | G40: =D40*F40*E40 -> 3403.8883 | H40: =G40*Assumptions!$D$18 -> 1701.9441 | I40: =H40*Assumptions!$D$19 -> 340.38883 | J40: =M39*Assumptions!$D$24 -> 13.580339 | K40: =M28*Assumptions!$D$25 -> 26.005383 | L40: =I40+J40+K40 -> 379.97455 | M40: =L40+M39*(1-Assumptions!$D$23) -> 834.91589 | N40: =IF(A40>=Assumptions!$D$11,Assumptions!$D$12,Assumptions!$D$10) -> 29 | O40: =M40*N40 -> 24212.561 | P40: =Assumptions!$D$29 -> 10 | Q40: =Assumptions!$D$30 -> 0.016 | R40: =M40*P40*Q40 -> 133.58654 | S40: =O40-R40 -> 24078.974 | T40: =IF(O40=0,0,S40/O40) -> 0.99448276

Sheet Forecast - Expansion
